<mujoco model="rotary_double_pendulum">
    <compiler angle="radian" coordinate="local" />
    <option timestep="0.004" gravity="0 0 -9.81" integrator="RK4" />

    <default>
        <joint limited="true" damping="0.0024" />
        <geom type="capsule" friction="1 0.1 0.1" size="0.01" rgba="0.2 0.6 0.8 1" />
    </default>

    <worldbody>
        <geom name="floor" pos="0 0 -3.0" rgba="0.8 0.9 0.8 1" size="40 40 40" type="plane" />

        <!-- Base -->
        <body name="base" pos="0 0 0">
            <site name="z_axis_marker" pos="0 0 -0.5" size="0.05 0.5" rgba="0 0 1 0.3"
                type="cylinder" />

            <!-- Rotary arm -->
            <body name="rotary_arm" pos="0 0 0">
                <joint name="rotary_motor" type="hinge" axis="0 0 1" limited="false" />
                <!-- <inertial pos="0 0 0.10795" mass="0.2570" diaginertia="0.001 0.001 0.001" /> -->
                <!-- From origin to tip (along X axis) -->
                <geom fromto="0 0 0 0.2159 0 0" size="0.01" rgba="0.2 0.6 0.9 1" mass="0.2570" />
                <site name="com_rotary_arm" pos="0.10795 0 0" size="0.012" rgba="1 0 0 1" />

                <!-- Link 1 (short pendulum) -->
                <body name="link1" pos="0.2159 0 0">
                    <joint name="hinge1" type="hinge" axis="1 0 0" limited="false" />
                    <!-- <inertial pos="0 0 0.1" mass="0.097" diaginertia="0.001 0.001 0.001" /> -->
                    <!-- From joint upward (along Z) -->
                    <geom fromto="0 0 0 0 0 0.2" size="0.01" rgba="1 0.6 0.2 1" mass="0.097" />
                    <site name="com_link1" pos="0 0 0.1635" size="0.012" rgba="0 0 1 1" />
                    <!-- 在link1末端添加重物 -->
                    <geom name="weight1" type="sphere" pos="0 0 0.2" size="0.02" mass="0.1410"
                        rgba="0.5 0.5 0.5 1" />

                    <!-- Link 2 (medium pendulum) -->
                    <body name="link2" pos="0 0 0.2">
                        <!-- <joint name="hinge2" type="hinge" axis="1 0 0" limited="false" /> -->
                        <!-- <joint name="hinge2" type="hinge" axis="1 0 0" limited="true"
                            range="-0.7 0.7" /> -->
                        <!-- <inertial pos="0 0 0.16825" mass="0.127" diaginertia="0.001 0.001
                        0.001" /> -->

                        <!-- From joint upward -->
                        <geom fromto="0 0 0 0 0 0.3365" size="0.01" rgba="0.2 0.8 0.4 1"
                            mass="0.127" />
                        <site name="com_link2" pos="0 0 0.1778" size="0.012" rgba="0 0 0 1" />
                        <!-- 在link2末端添加标志 -->
                        <site name="flag" pos="0 0 0.3365" size="0.012" rgba="1 0 0 1"
                            type="sphere" />
                    </body>
                </body>
            </body>
        </body>
    </worldbody>

    <actuator>
        <!-- Rotary base actuator -->
        <motor name="rotary_motor_act" joint="rotary_motor" ctrlrange="-1 1" gear="5" />
    </actuator>
</mujoco>